---
path: '/osa-6/3-fel'
title: 'Förbered dig på fel'
hidden: false
---

<text-box variant='learningObjectives' name='Lärandemål'>

Efter den här delen

* vet du hur du kan behandla icke-valida indata
* vet du vad som menas med undantag i programmeringskontext
* känner du till de vanligaste typerna av undantag i Python
* kan du behandla undantag i dina egna program.

</text-box>

Det finns två grundläggande kategorier av fel som uppkommer i program

* fel i syntax, som förhindrar körandet av ett program
* fel som sker medan programmet körs, och stoppar programmet

Fel i den första kategorin är vanligtvis enkla att korrigera eftersom Pythontolken berättar var felet ligger när man försöker köra programmet. Vanliga syntaxfel beror på kolon som fattas på någon inledande rad eller ett citattecken som fattas i slutet av en sträng.

Fel i den andra kategorin är ibland svårare att hitta, eftersom de endast sker vid något visst ställe i programmet i vissa situationer. Programmet kanske fungerar helt bra i de flesta situationer, men så finns det någon marginell situation då programmet stannar upp på grund av ett fel. Nu ska vi se hur vi kan behandla de här felen.

## Validering av indata

Flera fel som uppkommer då ett program körs beror på indata som är i fel format på något sätt. Här är några exempel:

* obligatoriska fält som fattas eller är tomma, till exempel tomma strängar i fall där strängens längd har betydelse
* negativa värden i fall där endast positiva värden är giltiga, till exempel -15 st. av en ingrediens i ett recept
* filer som saknas eller som har skrivfel i sina namn
* värden som är för stora eller för små, till exempel då vi arbetar med datum och klockslag
* icke-giltiga index, till exempel om vi försöker komma åt index 3 i strängen "hej"
* värden av fel typ, till exempel en sträng då vi förväntar oss ett heltal.

Till all lycka kan vi som programmerare förbereda oss för de flesta felen. Vi ser på ett program som frågar efter användarens ålder och kollar att siffran är giltig (mellan noll och 150):

```python
alder = int(input("Ange din ålder: "))
if alder >= 0 and alder <= 150:
    print("Acceptabel ålder")
else:
    print("Felaktig ålder")
```

<sample-output>

Ange din ålder: **25**
Acceptabel ålder

</sample-output>

<sample-output>

Ange din ålder: **-3**
Felaktig ålder

</sample-output>

Så länge användaren ger ett heltal verkar valideringen fungera som den ska. Men om användaren ger en sträng?

<sample-output>

Ange din ålder: **tjugotre**
ValueError: invalid literal for int() with base 10: 'tjugotre'

</sample-output>

Funktionen `int` kan inte behandla strängen `tjugotre` som ett heltal. Programmet stoppas och ett felmeddelande skrivs ut.

## Undantag

Fel som sker när programmet redan körs kallas undantag (exception). Det är möjligt att förbereda sig för undantag, så att programmet fortsätter köra även om undantag sker.

Undantag behandlas i Python med satserna `try` och `except`. Idén är att om något inom `try`-blocket orsakar ett undantag, kommer Python söka efter ett motsvarande `except`-block och köra koden under det blocket – och så fortsätter programmet att köra som normalt.

Låt oss ändra på exemplet ovan så att programmet är förberett för undantag av typen `ValueError`:

```python
try:
    alder = int(input("Ange din ålder: "))
except ValueError:
    alder = -1

if alder >= 0 and alder <= 150:
    print("Acceptabel ålder")
else:
    print("Felaktig ålder")
```

<sample-output>

Ange din ålder: **tjugotre**
Felaktig ålder

</sample-output>

Vi kan använda `try`-blocket för att markera att koden inom blocket möjligtvis kan orsaka ett fel. I `except`-satsen som direkt följer blocket nämns det felet vi kan förvänta oss. I exemplet ovan nämnde vi bara `ValueError`-undantaget. Om något annat fel skulle ha uppstått, skulle programmet ändå ha avslutats oavsett `try`- och `except`-blocken.

I exemplet ovan, om ett fel sker, tilldelas `alder` värdet `-1`. Det här är ett icke-giltigt värde som programmet redan sedan tidigare kan reagera på, eftersom programmet förväntar sig ett värde mellan noll och 150.

I det följande exemplet har vi funktionen `las_heltal` som ber användaren att ge ett heltal. Funktionen är också redo för icke-giltiga värden och fortsätter att fråga efter ett heltal tills ett giltigt värde har angetts.

```python
def las_heltal():
    while True:
        try:
            indata = input("Ange heltal: ")
            return int(indata)
        except ValueError:
            print("Felaktiga indata")

siffra = las_heltal()
print("Tack!")
print(siffra, "upphöjt till tre är", siffra**3)
```

<sample-output>

Ange heltal: **kolme**
Felaktiga indata
Ange heltal: **aybabtu**
Felaktiga indata
Ange heltal: **5**
Tack!
5 upphöjt till tre är 125

</sample-output>

Ibland räcker det med att fånga undantag med en try-except-struktur utan att göra något speciellt därtill. Vi kan alltså ignorera situationen i `except`-blocket.

Om vi ändrar på exemplet ovan så att vi endast accepterar heltal som är under 100, skulle det kunna se ut så här:

```python
def las_litet_heltal():
    while True:
        try:
            indata = input("Ange heltal: ")
            siffra = int(indata)
            if siffra < 100:
                return siffra
        except ValueError:
            pass # den här instruktionen gör inget

        print("Felaktiga indata")

siffra = las_litet_heltal()
print(siffra, "upphöjt till tre är", siffra**3)
```

<sample-output>

Ange heltal: **kolme**
Felaktiga indata
Ange heltal: **1000**
Felaktiga indata
Ange heltal: **5**
Tack!
5 upphöjt till tre är 125

</sample-output>

Nu innehåller except-blocket endast instruktionen `pass`, som inte gör något. Python tillåter inte tomma block, så instruktionen är nödvändig.

<programming-exercise name='Läsa indata' tmcname='osa06-17_lasa_indata'>

Skapa funktionen `las` som ber användaren ange ett tal, tills användaren anger ett tal som är inom intervallet som angivits. Funktionen ska returnera talet användaren gett.

Exempel:

```python
siffra = las("Ange siffra: ", 5, 10)
print("Du gav siffran:", siffra)
```

<sample-output>

Ange siffra: **seitsemän**
Siffran ska vara ett heltal i intervallet 5-10
Ange siffra: **-3**
Siffran ska vara ett heltal i intervallet 5-10
Ange siffra: **8**
Du gav siffran: 8

</sample-output>

</programming-exercise>

## Vanliga fel

Här är en samling av vanliga fel som du sannolikt kommer att stöta på. Vi kollar också i hurdana situationer dessa kan uppstå.

**ValueError**

Det här felet uppstår vanligtvis då ett argument som ges till en funktion på något sätt är ogiltigt. Till exempel anropet `float("1,23")` orsakar ett fel eftersom decimaler alltid skiljs åt med punkt i Python.

**TypeError**

Det här felet uppstår då ett värde har fel typ. Om vi till exempel anropar `len(10)` får vi ett fel, eftersom funktionen `len` kräver ett värde vars längd kan räknas – till exempel en sträng eller lista.

**IndexError**

Det här felet uppstår då vi försöker hänvisa till ett index som inte finns. Till exempel uttrycket `"abc"[5]` orsakar ett fel eftersom strängen i fråga inte har indexet 5.

**ZeroDivisionError**

Det här felet uppstår då man försöker dividera med noll. Om vi till exempel försöker ta reda på medeltalet av värden i en lista med uttrycket `sum(min_lista) / len(min_lista)` och listans längd är noll, kommer vi att få ett fel.

**Undantag när filer behandlas**

Några vanliga undantag som kan uppstå när filer behandlas är `FileNotFoundError` (filen som man försöker komma åt finns inte), `io.UnsupportedOperation` (man försöker göra något åt filen som inte tillåts i det läge filen öppnats i) och `PermissionError` (programmet har inte åtkomst till filen).

## Behandla flera undantag samtidigt

Ett `try`-block kan följas av flera `except`-block. Det här programmet kan exempelvis behandla situationer där `FileNotFoundException`- och `PermissionError`-undantagen uppkommer:

```python
try:
    with open("exempel.txt") as fil:
        for rad in fil:
            print(rad)
except FileNotFoundError:
    print("Filen exempel.txt hittades ej")
except PermissionError:
    print("Har inte åtkomst till filen exempel.txt")
```

Ibland är det inte nödvändigt att specificera det fel som programmet förbereder sig för. Speciellt då man arbetar med filer, räcker det med att veta att något fel har skett och därmed avsluta programmet på ett säkert sätt. Man behöver inte alltid veta varför ett fel har uppstått. Om vi vill vara förberedda på alla möjliga undantag kan vi använda `except`-blocket utan att specificera felet:

```python
try:
    with open("exempel.txt") as fil:
        for rad in fil:
            print(rad)
except:
    print("Fel i läsandet av filen")
```

Obs! Den här `except`-satsen körs nu i alla möjliga felsituationer – det här gäller också misstag som programmeraren gjort. Endast syntaxfel kommer att orsaka fel som förhindrar programmet från att köras – detta eftersom den här typen av fel inte låter koden köras över huvud taget.

Till exempel det här programmet kommer alltid att ge ett fel, eftersom variabelnamnet `fil` har skrivits fel på den tredje raden:

```python
try:
    with open("exempel.txt") as fil:
        for rad in fli:
            print(rad)
except:
    print("Fel i läsandet av filen")
```

Ett `except`-block kan gömma bakomliggande fel. Problemet här berodde inte på hur filer behandlades utan på en variabel med inkorrekt namn. Utan ett `except`-block skulle vi kunna se vilket fel som orsakats och kunde därmed hitta källan till felet enklare. Därför lönar det sig att endast använda `except`-blocket för fördefinierade specifika typer av fel.

## Förmedling av undantag

Om körandet av en funktion orsakar ett undantag som inte behandlas kommer undantaget att förmedlas till koden som anropat koden och fortsätta kliva upp till huvudfunktionen. Om felet inte här heller behandlas, kommer programmet att stoppas och undantaget skrivs ut för användaren att se.

I det följande exemplet har vi funktionen `test`. Om den orsakar ett undantag, kommer det inte att behandlas inne i funktionen utan i huvudfunktionen:

```python
def test(x):
    print(int(x) + 1)

try:
    siffra = input("Ange siffra: ")
    test(siffra)
except:
    print("Något gick fel")
```

<sample-output>

Ange siffra: **tre**
Något gick fel

</sample-output>

## Åstadkomma undantag

Du kan åstadkomma undantag med instruktionen `raise`. Det kan verka som en konstig idé att själv åstadkomma fel i ditt program, men det kan vara nyttigt i olika situationer.

Det kan till exempel löna sig att åstadkomma ett fel när man märker icke-valida parametrar. Hittills har vi skrivit ut meddelanden när vi har validerat indata, men om vi gör en funktion som ska köras från något annat ställe så kan det hända att en utskrift inte noteras när funktionen anropas. Att åstadkomma ett fel kan göra debuggande enklare.

I det följande exempel har vi en funktion som räknar ut fakulteten av en siffra (t.ex. för siffran fem är fakulteten 1 * 2 * 3 * 4 * 5). Om argumentet som ges till funktionen är negativt, kommer ett fel att åstadkommas:

```python
def fakultet(n):
    if n < 0:
        raise ValueError("Negativt värde: " + str(n))
    k = 1
    for i in range(2, n + 1):
        k *= i
    return k

print(fakultet(3))
print(fakultet(6))
print(fakultet(-1))
```

<sample-output>

6
720
Traceback (most recent call last):
  File "testi.py", line 11, in <module>
    print(fakultet(-1))
  File "testi.py", line 3, in fakultet
    raise ValueError("Negativt värde: " + str(n))
ValueError: Negativt värde: -1

</sample-output>


<programming-exercise name='Validera givna argument' tmcname='osa06-18_validera_argument'>

Skapa funktionen `ny_person(namn: str, alder: int)` som skapar och returnerar en tuple som representerar en person. Det första elementet är ett namn och det andra en ålder.

Om de givna argumenten är felaktiga, ska funktionen orsaka ett `ValueError`-undantag.

Felaktiga argument är:

* tom sträng som namn
* ett namn som inte består av minst två ord
* ett namn som är längre än 40 tecken
* en negativ ålder
* en ålder som överstiger 150

</programming-exercise>

<programming-exercise name='Felaktiga lottorader' tmcname='osa06-19_lottorader'>

I filen `lottorader.csv` har man lagrat lottorader enligt följande exempel:

<sample-data>

vecka 1;5,7,11,13,23,24,30
vecka 2;9,13,14,24,34,35,37
o.s.v. ...

</sample-data>

Först ska rubriken `vecka x` komma, följt av sju siffror i intervallet 1-39.

Filen är dock delvis skadad. Här följer exempel på felaktiga rader.

Veckonummer felaktigt:

<sample-data>

vecka zzc;1,5,13,22,24,25,26

</sample-data>

Ett eller flera felaktiga nummer:

<sample-data>

vecka 22;1,**,5,6,13,2b,34

</sample-data>

Fel antal nummer:

<sample-data>

vecka 13;4,6,17,19,24,33

</sample-data>

För små eller stora nummer:

<sample-data>

vecka 39;5,9,15,35,39,41,105

</sample-data>

Samma nummer förekommer flera gånger på samma rad:

<sample-data>

vecka 41;5,12,3,35,12,14,36

</sample-data>

Skapa funktionen `filtrera_felaktiga()` som skapar filen `korrigerade_rader.csv`. Filen ska innehålla de korrekta raderna från den ursprungliga filen.

</programming-exercise>

<quiz id="3b7efa6e-86d8-5934-a122-2431a3ed7161"></quiz>
